# [协程](https://github.com/chaleaoch/gitblog/issues/39)


Table of Contents
=================

   * [最简单的生成器](#最简单的生成器)
   * [终止协程和异常处理](#终止协程和异常处理)
      * [generator.throw 和 generator.close](#generatorthrow-和-generatorclose)
   * [返回值](#返回值)
   * [yield from](#yield-from)
   * [async await](#async-await)
      * [async](#async)
      * [await](#await)
   * [async with](#async-with)
   * [async for](#async-for)
   * [协程对象](#协程对象)
      * [原生协程和生成器协程的区别](#原生协程和生成器协程的区别)
   * [一个例子](#一个例子)

\*\*\*\*\*\*\*\*\*\*\*\*\*\*\*\*\*\*\*\*\*\*\*\*\*\*\*\*\*\*\*\*\*\*\*\*\*\*\*\*\*\*\*\*\*\*\*\*\*\*\*\*\*\*\*\*\*\*\*\*
1. yield item 会产出一个值， 提供给 next(...)  

1. datum = yield,  后面为空,将产出None

    - .send(datum) 将值推送给协程

# 最简单的生成器

```python
>>> def simple_coro2(a):
... print('-> Started: a =', a)
... b = yield a
... print('-> Received: b =', b)
... c = yield a + b
... print('-> Received: c =', c)
...
>>> my_coro2 = simple_coro2(14)
>>> from inspect import getgeneratorstate
>>> getgeneratorstate(my_coro2) ➊
'GEN_CREATED'
>>> next(my_coro2) ➋
-> Started: a = 14
14
>>> getgeneratorstate(my_coro2) ➌
'GEN_SUSPENDED'
>>> my_coro2.send(28) ➍
-> Received: b = 28
42
>>> my_coro2.send(99) ➎
-> Received: c = 99
Traceback (most recent call last):
File "<stdin>", line 1, in <module>
StopIteration
>>> getgeneratorstate(my_coro2) ➏
'GEN_CLOSED'
```

- b = yield a
 -- a是给调用者的返回值, b是接收值

- 初始调用 必须是 next(my_coro2 ) 或者是 my_coro2 .send(None), 否则会报错

- 生成器也可以有初始值参数

- 执行到末尾会触发 StopIteration
 异常

# 终止协程和异常处理 

```python
>>> from coroaverager1 import averager
>>> coro_avg = averager()
>>> coro_avg.send(40) # ➊
40.0
>>> coro_avg.send(50)
45.0
>>> coro_avg.send('spam') # ➋
Traceback (most recent call last):
...
TypeError: unsupported operand type(s) for +=: 'float' and 'str'
>>> coro_avg.send(60) # ➌
Traceback (most recent call last):
File "<stdin>", line 1, in <module>
StopIteration

```

- 如果协程内部有异常,将会向上传导, 如果再次给协程发消息(.send()), 将会触发StopIteration 异常.

## generator.throw 和 generator.close 

- generator.throw

    - 在生成器暂停的位置引发 `type` 类型的异常，并返回该生成器函数所产生的下一个值

    - 如果生成器没有产生下一个值就退出，则将引发 `StopIteration` 异常

    - 如果生成器函数没有捕获传入的异常，或引发了另一个异常，则该异常会被传播给调用者

```python
def echo(value=None):
    print("Execution starts when 'next()' is called for the first time.")
    try:
        while True:
            # value = yield value
            try:
                value = yield value
            except Exception as e:
                yield 333
    finally:
        print("Don't forget to clean up when 'close()' is called.")


generator = echo(1)
print(next(generator))


print(next(generator))

print(generator.send(2))

generator.throw(TypeError, "spam")

generator.close()

```

- generator.close

    - 在生成器函数暂停的位置引发 `GeneratorExit`

        - GeneratorExit 和 Exception 是兄弟关系. 不是继承关系

    - 如果之后生成器函数正常退出、关闭或引发 `GeneratorExit` (由于未捕获该异常) 则关闭并返回其调用者

    - 如果生成器产生了一个值，关闭会引发 `RuntimeError`

    -  如果生成器引发任何其他异常，它会被传播给调用者

    - 如果生成器已经由于异常或正常退出则 `close()` 不会做任何事。

```python
def echo(value=None):
    print("Execution starts when 'next()' is called for the first time.")
    try:
        while True:
            # value = yield value
            try:
                value = yield value
            except GeneratorExit as e:
                yield 456
            except Exception as e:
                print(123)
    finally:
        print("Don't forget to clean up when 'close()' is called.")
        return 000


generator = echo(1)
print(next(generator))


print(next(generator))

print(generator.send(2))

# generator.throw(TypeError, "spam")

print(generator.close())
print(666)

```

# 返回值

生成器返回的还是一个异常,但是异常的value中有返回值

```python
def averager():
	total = 0.0
	count = 0
	average = None
	while True:
		term = yield
		if term is None:
			break ➊
		total += term
		count += 1
		average = total/count
	return Result(count, average) 


>>> coro_avg = averager()
>>> next(coro_avg)
>>> coro_avg.send(10)
>>> coro_avg.send(30)
>>> coro_avg.send(6.5)
>>> try:
... coro_avg.send(None)
... except StopIteration as exc:
... result = exc.value
...
>>> result
Result(count=3, average=15.5)

```

# yield from

- 建立双向通道 -- 实现子协程,协程和协程调用者直连

```python
final_result = {}
def sales_sum(pro_name):
    total = 0
    nums = []
    while True:
        x = yield
        print(pro_name+"销量: ", x)
        if not x:
            break
        total += x
        nums.append(x)
    return total, nums


def middle(key):
    while True:
        final_result[key] = yield from sales_sum(key)
        print(key+"销量统计完成！！.")

def main():
    data_sets = {
        "bobby牌面膜": [1200, 1500, 3000],
        "bobby牌手机": [28,55,98,108 ],
        "bobby牌大衣": [280,560,778,70],
    }
    for key, data_set in data_sets.items():
        print("start key:", key)
        m = middle(key)
        m.send(None) # 预激middle协程
        for value in data_set:
            m.send(value)   # 给协程传递每一组的值
        m.send(None)
    print("final_result:", final_result)

if __name__ == '__main__':
    main()

```

# async await

## async

用于声明协程

```python
async def read_data(db):
    pass
```

- async def函数必定是协程，即使里面不含有await语句。

- 如果在async函数里面使用yield或yield from语句，会引发SyntaxError异常。

- 在CPython内部，引入两个新的代码对象标识（code object flags）：

    - CO_COROUTINE表示这是原生协程。

    - CO_ITERABLE_COROUTINE表示这是用生成器实现的协程，但是和原生协程兼容。（用装饰器types.coroutine()装饰过的生成器协程）

- 调用一个普通生成器，返回一个生成器对象（generator object）；相应的，调用一个协程返回一个协程对象（coroutine object）。

- 原生协程不再抛出StopIteration异常，因为抛出的StopIteration异常会被包装（wrap）成一个RuntimeError异常。

- 如果一个协程从未await等待就被垃圾收集器销毁了，会引发一个RuntimeWarning异常.

## await

用于获取结果

```python
async def read_data(db):
    data = await db.fetch('SELECT ...')
    ...

```

- 挂起read_data的执行，直到db.fetch执行完毕并返回结果。

- await只接受awaitable对象，awaitable对象是以下的其中一个：

    - 一个原生协程对象（由一个原生协程函数返回）

    - 用装饰器types.coroutine()装饰的一个“生成器实现的协程”对象

    - 一个有__await__方法的对象（__await__方法返回的一个迭代器, 或生成器）

- 每个yield from调用链条都会追溯到一个最终的yield语句, 每个await最终会被await调用链条上的某个yield语句挂起

- 在CPython C API，有tp_as_async.am_await函数的对象，该函数返回一个迭代器（类似__await__方法）

- 如果在async def函数之外使用await语句，会引发SyntaxError异常。这和在def函数之外使用yield语句一样。

- 如果await右边不是一个awaitable对象，会引发TypeError异常。

# async with

添加了两个新的魔术方法：__aenter__和__aexit__，它们必须返回一个awaitable。

在async def函数之外使用async with则会引发SyntaxError异常。

```python
class AsyncContextManager:
    async def __aenter__(self):
        await log('entering context')

    async def __aexit__(self, exc_type, exc, tb):
        await log('exiting context')

async with EXPR as VAR:
    BLOCK

# 语意等同于
mgr = (EXPR)
aexit = type(mgr).__aexit__
aenter = type(mgr).__aenter__(mgr)
exc = True

VAR = await aenter
try:
    BLOCK
except:
    if not await aexit(mgr, *sys.exc_info()):
        raise
else:
    await aexit(mgr, None, None, None)

# 例子
async def commit(session, data):
    ...

    async with session.transaction():
        ...
        await session.update(data)
        ...

# 加锁
async with lock:
    ...

```

# async for

1. 对象必须实现一个__aiter__方法（或者，如果使用CPython C API，需要定义tp_as_async.am_aiter），返回一个异步迭代器对象，这个异步迭代器对象在每次迭代时会返回一个awaitable。

1. 一个异步迭代器必须实现一个__anext__方法（或者，如果使用CPython C API，需要定义tp_as_async.am_anext），在每次迭代时返回一个awaitable。

1. 要停止迭代，__anext__必须抛出一个StopAsyncIteration异常。

1. 如果在async def函数外使用async for，则引发SyntaxError异常

```python
class AsyncIterable:
    async def __aiter__(self):
        return self

    async def __anext__(self):
        data = await self.fetch_data()
        if data:
            return data
        else:
            raise StopAsyncIteration

    async def fetch_data(self):
        ...

# 使用
async for TARGET in ITER:
    BLOCK
else:
    BLOCK2

```

# 协程对象

## 原生协程和生成器协程的区别

1. 原生协程对象不实现__iter__和__next__方法，因此，不能对其进行迭代（如for...in循环），也不能传递给iter()，list()，tuple()及其它内置函数。如果尝试对其使用__iter__或__next__方法，会引发TypeError异常。

1. 未装饰的生成器不能yield from一个原生协程，这样做会引发TypeError异常。

1. “基于生成器的协程”在经过 @asyncio.coroutine装饰后，可以yield from原生协程对象。

1. 对于原生协程对象和原生协程函数，调用inspect.isgenerator()和inspect.isgeneratorfunction()会返回False。

# 一个例子

二逼例子

```text
import time


def demo4():
    async def washing1():
        print('washer1 finished')
        return 666

    a = washing1()
    try:
        a.send(None)
    except StopIteration as e:
        print (e.value)
    time.sleep(2)
    print(4)


if __name__ == '__main__':
    demo4()

```

普通例子

```python
import asyncio


def demo4():
    async def washing1():
        await asyncio.sleep(3)  # 使用 asyncio.sleep(), 它返回的是一个可等待的对象
        print('washer1 finished')

    async def washing2():
        await asyncio.sleep(2)
        print('washer2 finished')

    async def washing3():
        await asyncio.sleep(5)
        print('washer3 finished')

    loop = asyncio.get_event_loop()

    tasks = [
        washing1(),
        washing2(),
        washing3(),
    ]

    loop.run_until_complete(asyncio.wait(tasks))

    loop.close()


if __name__ == '__main__':
    demo4()

```

